Workbook
Name _Hlk195095072: EĞİTİMLER!#REF!
Name _Hlk195479915: EĞİTİMLER!$A$2
Name GrafikYılı: YEAR(#REF!)

Sheet İş akış 2026
D2: SÖZLEŞME HAZIRLIK VE İHALE SÜRECİ | F2: SÖZLEŞMENİN İMZALANMASI VE İŞE BAŞLANMASI | J2: AYLIK HAKEDİŞLERİN YAPILMASI VE İŞLERİN GEÇİCİ KABULE HAZIR HALE GETİRİLMESİ | P2: KESİN HAKEDİŞ | Q2: KESİN KABUL SÜRECİ VE KESİN TEMİNAT İADELERİ
D6: Sözleşme Süreci,İhale Süreci | F6: Yer Teslimi Talebinin Yapılması | G6: Yer Tesliminin Yapılması ve onaylanması | H6: İş Programının Hazırlanması | I6: İş Programının Onaylanması | J6: Saha Çalışmalarının Başlaması | K6: 1.Hk. | L6: 2.Hk. | M6: 3.Hk. | N6: 4.Hk. | O6: 5.Hk.
J8: (SÇ) | K8: (SÇ) | L8: (SÇ) | M8: (SÇ) | N8: (SÇ) | O8: (SÇ) | P8: Kesin Hakediş İnceleme Süreci
D9: İhale Sonucu | E9: Sözleşmenin İmzalanması
P10: Son Durum Proje Kontrolü
P11: Saha Metraj Kontrolü
F12: =CONCATENATE((F14-E14),Formül!C3) -> 5Gün | G12: =CONCATENATE((G14-F14),Formül!C5) -> 10Gün | H12: =CONCATENATE((H14-G14),Formül!C7) -> 10Gün | I12: =CONCATENATE((I14-H14),Formül!C7) -> 5Gün | P12: Yeni Malzeme Mutabakatı
P13: Demontaj Malzeme Mutabakatı
B14: GENEL HÜKÜMLER-ÖZEL HÜKÜMLER | D14: 46062 | E14: =Formül!B3 -> 46059 | F14: =Formül!B4 -> 46064 | G14: =Formül!B5 -> 46074 | H14: =Formül!B6 -> 46084 | I14: =Formül!B7 -> 46089 | J14: =Formül!$B7 -> 46089 | K14: =Formül!$B8 -> 46096 | L14: =Formül!$B9 -> 46126 | M14: =Formül!$B10 -> 46156 | N14: =Formül!$B11 -> 46187 | O14: =Formül!$B12 -> 46218 | P14: =Formül!$B13 -> 46263 | Q14: =Formül!$B14 -> 46293
D16: KONU | E16: İÇERİK
B17: GENEL HÜKÜMLER | C17: MADDE 6 | D17: Sözleşmenin imzalanması | E17: =E14 -> 46059
B18: GENEL HÜKÜMLER | C18: MADDE 7 | D18: Teminata ilişkin hükümler | E18: Sözleşme belirtilen miktarda kesin teminat getirilmesi
B20: GENEL HÜKÜMLER | C20: MADDE 7 | D20: Teminata ilişkin hükümler | E20: Sözleşme bedeli üzerinden %10 malzeme teminatının getirilmesi.
B22: İSG-Ç ŞARTNAMESİ | D22: İş Sağlığı ve Güvenliği | E22: İSG-Ç gereklilikleri yerine getirilir ve poliçelerini tamamlar.
B23: Hazırlayacak Sorumlu
A24: YÜKLENİCİ | B24: İSG UZMANI | C24: OSGB
A25: X | D25: Yüklenici Firma İşe Başlama Gereklilikleri (PERSONELE İLİŞKİN BELGELER) | E25: 7. Personel Özlük Evrakları
A26: X | E26: 7.1. Çalışanın T.C. kimlik kartı fotokopisi
A27: X | E27: 7.2. Çalışan için son 3 (üç) ay içerisinde alınmış adli sicil kaydı
A28: X | E28: 7.3. Çalışanın SGK işe giriş bildirgesi
A29: X | E29: 7.4. Çok tehlikeli işlerde çalışabileceğine dair işe giriş periyodik sağlık raporu (KVKK’ya uygun, Ek-2 formatında, işyeri hekimi onaylı) ve tetkikleri (Akciğer grafisi, solunum fonksiyon testi, odyometri, EKG, hemogram, açlık kan şekeri, AST, ALT, üre, kreatinin, TSH, kan grubu kartı, tetanoz aşı kartı ve işyeri hekimi tarafından talep edilmesi halinde ek tetkikler yaptırılacaktır.)
A30: X | E30: 7.5. YEDAŞ Yüklenici Firma Yapım İşleri İSG-Ç Şartnamesi Madde 6.8, Tablo-2 Yüklenici eğitim matrisinde belirtilen eğitimlere uygun kayıtlar (eğitim katılım formları, sertifikalar)
A31: X | E31: 7.6. Mesleki yeterlilik sertifikası (operatörlük belgesi, kaynakçı belgesi, ustalık belgesi, yaptığı isle ilgili diploması vb.)
A32: X | E32: 7.7. Çalışan adına düzenlenmiş ve içeriğinde “teslim eden”, “teslim alan” kişilerin imzalarının, “teslim edilen ve teslim alınan tarihlerin”, “teslim edilen ve teslim alınan ekipmanların isimlerinin” bulunduğu ekip ve kişisel koruyucu donanım zimmet formu
A33: X | E33: 7.8. Çalışan tarafından imzalanmış genel ve yaptığı işe özgü İSG-Ç talimat ve taahhütnamesi
A34: X | E34: 7.9. Fazla çalışma muvafakatnamesi
A35: X | E35: 7.10. Kişisel Verilerin Paylaşılmasına Yönelik Mutabakat Formu
A36: X | E36: 7.11. Yüklenicinin Hizmet Alacağı Çalışanlar İçin Görevlendirme Yazısı
A37: X | E37: 7.12. Yüklenicinin Hizmet Alacağı Firmalar ile Yapacağı Sözleşme, Protokol, Tutanak vb. (Operatör vb.)
A39: YEDAŞ | D39: İşe Başlama Ve Güncelleştirme Yapıldıkça Yenilenecek Evraklar (FİRMAYA İLİŞKİN BELGELER) | E39: 1. İSG-Ç Planı | F39: X | J39: X | K39: X | L39: X | M39: X | N39: X | O39: X
A40: YEDAŞ | E40: 2. Acil Durum ve Kurtarma Planı | F40: X | J40: X | K40: X | L40: X | M40: X | N40: X | O40: X
A41: YEDAŞ | E41: 3. Kaldırma, Taşıma, İletme Planı | F41: X | J41: X | K41: X | L41: X | M41: X | N41: X | O41: X
B42: X | E42: 4. Eğitim Planı | F42: X | J42: X | K42: X | L42: X | M42: X | N42: X | O42: X
B43: X | C43: X | E43: 5. Risk Değerlendirmesi ve Çevre Etki Analizi | F43: X | J43: X | K43: X | L43: X | M43: X | N43: X | O43: X
A44: YEDAŞ | E44: 6. Yöntem Bildirimi | F44: X | J44: X | K44: X | L44: X | M44: X | N44: X | O44: X
A45: X | E45: 8.1. Makine, ekipman listesi | F45: X | J45: X | K45: X | L45: X | M45: X | N45: X | O45: X
A46: X | E46: 8.2. Periyodik kontroller | F46: 6 AYLIK PERİYOTLARLA | J46: X | K46: X | L46: X | M46: X | N46: X | O46: X
A47: X | E47: 8.3. Bakım, onarım formları (faturaları vb.) | F47: X | J47: X | K47: X | L47: X | M47: X | N47: X | O47: X
A48: X | E48: 8.4. Mevzuata göre yaptırılmış araç sigortaları | F48: X | J48: X | K48: X | L48: X | M48: X | N48: X | O48: X
E49: 9. Atama ve Görevlendirmeler | F49: X
...

Sheet EĞİTİMLER
A2: No | B2: Eğitimin Adı | C2: Eğitimin İçeriği | D2: Süre | E2: Süre | F2: Katılımcı Profili | G2: Eğitmen | H2: Eğitim Dönemi
A3: 1 | B3: Temel İSG-Ç Eğitimi | C3: *Çalışanların İş Sağlığı ve Güvenliği Eğitimleri Hakkında Yönetmelik’te belirtilen konular | D3: 12 sa | E3: 2 | F3: Tüm çalışanlar | G3: OSGB | H3: İşe girişte (çalışan sahaya çıkmadan önce)
C4: *Elektriksel Güvenlik
C5: *Çevre ve yol güvenliği
C6: * Kaldırma taşıma işlerinde güvenlik
C7: * Kaynak ve/veya kesme işlerinde güvenlik
C8: Kazı işlerinde güvenlik
C9: *Uygulamalı KKD kullanma eğitimi
C10: *Sahada karşılaşılan riskler ve önlemler
C11: * Trafik kuralları, güvenli sürüş teknikleri ve trafik kazaları
A12: 2 | B12: İş Sağlığı Eğitimi | C12: *Çalışanların İş Sağlığı ve Güvenliği Eğitimleri Hakkında Yönetmelik’te belirtilen konular | D12: 4 sa | E12: 0.5 | F12: Tüm çalışanlar | G12: OSGB | H12: İşe girişte (çalışan sahaya çıkmadan önce)
C13: *Temel ilkyardım bilgileri
A14: 3 | B14: İşe Başlangıç (Saha Oryantasyon Eğitimi) | C14: *Proje alanının tanıtılması | D14: 2 sa | E14: 0.25 | F14: Tüm çalışanlar | G14: YEDAŞ | H14: İşe girişte (çalışan sahaya çıkmadan önce)
C15: *Proje alanında yapılan/yapılacak işlerin tanıtılması
C16: *Genel proje kuralları
C17: *Kullanılacak KKD’ler
C18: *Çalışmalardan ya da çevreden kaynaklanacak tehlike ve riskler hakkında çalışanın bilgilendirilmesi
C19: *İş kazalarının tanımı ve iş kazalarının oluş ve önleme yolları
C20: *Güvenlik Kültürü, Emniyetli çalışma ve kaza önleme kuralları
C21: *Olası acil durumlar ve acil durumlarda personellerin sergilemesi gereken davranışlar
A22: 4 | B22: İşe Başlama Eğitimi | C22: *İSG’nin önemi | D22: 4 sa | E22: 0.5 | F22: Tüm çalışanlar | G22: C SINIFI/OSGB | H22: İşe girişte (çalışan sahaya çıkmadan önce)
C23: *YEDAŞ’ın İSG Vizyonu ve yüklenicilerden beklentileri
C24: *Ortak bir güvenlik kültürü oluşturma
C25: *İş yapım yöntemleri
C26: *Uygunsuzluk türleri ve yaptırımlar
A27: 5 | B27: Risk Değerlendirme Eğitimi | C27: *Tehlike-risk kavramları | D27: 4 sa | E27: 0.5 | F27: Risk Değerlendirme Ekibi Üyeleri | G27: OSGB | H27: İşe başlamadan önce
C28: *Risk değerlendirme aşamaları
C29: *Risk kontrol hiyerarşisi
C30: *Risk değerlendirme yöntemi
A31: 6 | B31: Acil Durum Eğitimi | C31: *Acil durumların tanımı | D31: 4 sa | E31: 0.5 | F31: Acil durum ekibinde yer alan çalışanlar | G31: OSGB | H31: İşe başlamadan önce
C32: *Acil durum iletişimi
C33: *Acil durum yönetimi
C34: *Acil durumlarda görev, yetki ve sorumluluklar
A35: 7 | B35: İSG-Ç Kurul Üyelerinin Eğitimi | C35: İSG-Ç Kurulları Hakkında Yönetmelik’te belirtilen konular | D35: 4 sa | E35: 0.5 | F35: İSG-Ç Kurul Üyeleri | G35: Mevzuata uygun eğitmen | H35: Toplanması gerektiği durumda ilk kuruldan önce
A36: 8 | B36: Sertifikalı İlkyardımcı Eğitimi | C36: İlkyardım Yönetmeliği’nde belirtilen konular | D36: 16 sa | E36: 2 | F36: İlkyardım Yönetmeliği’ne göre çalışanların min. %10’u (Sayı belirlenirken ekiplere göre dağılım dikkate alınmalıdır) | G36: OSGB | H36: İşe başlamadan önce
A38: 9 | B38: Yüksekte Çalışma Eğitimi (Teorik+Uygulamalı) | C38: *Demir, beton, ağaç direkte çalışma, * Merdivende çalışma | D38: 8 sa | E38: 1 | F38: Yüksekte çalışma yapan çalışanlar | G38: Mevzuata uygun eğitmen | H38: İşe başlamadan önce
C39: *Yüksekte çalışmada kullanılan KKD ve ekipmanların kullanımı
C40: *Uygulamalı eğitim
C41: *Yüksekte çalışanı kurtarma eğitimi
A42: 10 | B42: Yüksekte Güvenli Çalışma eğitimi | C42: *Elektrik dağıtım sektörü yüksekte çalışma uygulamaları | D42: 2 sa | E42: 0.25 | F42: Yüksekte çalışma yapan çalışanlar | G42: YEDAŞ tarafından uygun görülen eğitmen | H42: İşe başlamadan önce
...

Sheet cezalar2025
A1: MADDE NO | B1: YÜKLENİCİ SORUMLULUĞU | D1: BLOKE TUTARI | E1: VERİLEN SÜRE | F1: CEZA TUTARI | G1: NOT
A2: 26.13. | B2: 1 adet Elektrik Mühendisi şantiye şefi bulunduracaktır. | E2: 10 Gün | F2: 3000 TL | G2: Cezalı çalışma süresi 10(On) günü geçemez
A3: 26.14. | B3: Proje sürecinde yüklenicinin iş bu sözleşme kapsamında YEDAŞ’a sunması gereken bilgi ve belgeleri (Personel bilgisi, İş Planı, İlerleme raporu, sigorta vs.…) sözleşmede belirtilen ve proje yürütümü esnasında YEDAŞ ’ın bildireceği sürelerde sunmaz ise. | D3: - | E3: - | F3: %0.1 X Sözleşme Bedeli | G3: -
A4: 26.6. | B4: Yükleniciye teslim edilen yeni malzemeler için | D4: - | E4: 7 Gün | F4: Teslim edilmeyen yeni malzemeler için 2 yeni malzeme bedeli | G4: Kesin hesap yapımı sürecinde yapılan yeni malzeme mutabakatına istinaden yüklenici tarafından teslim edilemeyen malzemeler için uygulanır
A5: 10.8. | B5: Teslim edilmeyen demontaj malzemeleri için | D5: Proje Hakediş Tutarının 10%'u | E5: 7 Gün | F5: Teslim edilmeyen demontaj malzemeler için 1 yeni malzeme bedeli | G5: Mevcut durum saha tespit tutanağına göre yapılan demontaj malzeme mutabakatı sonucu teslim edilmemiş her demontaj kalemi için.
A6: 10.8. | B6: Sahada imalatı yapılan her türlü çalışma projelendirilerek hakediş döneminde hakkediş eki olarak sunulur | D6: Proje Hakediş Tutarının %5 'i | E6: - | F6: - | G6: -
A7: 10.8. | B7: Geçici kabul | D7: Proje Hakediş Tutarının %5 'i | E7: - | F7: - | G7: -
A8: 26.2. | B8: Yüklenicinin sözleşmeye uygun olarak işleri, iş programında belirtilen sürelerde (geçici kabule hazır hale getireceği tarihe kadar) bitirecektir. Bu durumun 5 projede meydana gelmesi durumunda sözleşme feshedilir. | D8: - | E8: - | F8: Proje Hakediş Tutarının %50 'i | G8: Her hakediş döneminde iş programına uyulacaktır.
A9: 26.7. | B9: Bildirimli kesintiler.Sistem işletme birimi, Kontrol heyeti ve Yüklenici Sorumlusu bir araya gelerek, kesintinin süresini belirler. | C9: YÜKLENİCİ kaynaklı sebeplerle enerji kesintisi belirlenen sürede gerçekleşmezse ya da geçerli bir sebep olmaksızın planlanan ve ilan edilen kesinti gerçekleşmeyip iptal olursa | D9: - | E9: - | F9: 25.000 (Yirmi Beş Bin) TL | G9: Her bir kesinti için
C10: Kesinti süresinin 0 dakika – 30 dakika arasında gecikmesi durumunda | D10: - | E10: - | F10: 10.000 (On Bin) TL | G10: Her bir kesinti için
C11: 30 dakika – 60 dakika arasında gecikmesi durumunda | D11: - | E11: - | F11: 25.000 (Yirmi Beş Bin) TL | G11: Her bir kesinti için
C12: 60 dakikayı geçmesi halinde | D12: - | E12: - | F12: 50.000 (Elli Bin) TL | G12: Her bir kesinti için
C13: Bir planlı kesinti süresinin 10 saati geçmesi halinde | D13: - | E13: - | F13: YÜKLENİCİ’den ilgili diğer cezaların yanı sıra YEDAŞ’ın tüketicilere ödemek zorunda olduğu Elektrik Dağıtımı ve Perakende Satışına İlişkin Hizmet Kalitesi Yönetmeliği’nin veya yürürlükte olan yönetmeliklerin ilgili maddeleri kapsamında hesaplanacak ceza bedelleri | G13: Ayrıca 10 saati aşan kesinti ya da süreden bağımsız herhangi bir kesinti nedeniyle oluşacak 3. Şahıs hasarları, hasar gören abonelerin talepleri ya da Kontrol Heyeti’nin tespiti dahilinde hesaplanacak olup söz konusu bedeller YÜKLENİCİ’den tahsil edilebilir.
A14: 26.8. | B14: Çalışma yapılan bölgede belirtilen standartlarda bilgilendirici levha bulundurulmaması durumunda | D14: - | E14: - | F14: 20.000 (yirmi bin) TL | G14: -
A15: 26.9. | B15: Müşterilerin, Yüklenici personelleriyle ilgili yapılan şikayetlerin şirketimiz tarafından yapılan değerlendirme neticesinde Yüklenici personelinin kusurlu bulunması durumunda olay ve olayla ilişkili Yüklenici personeli başına | D15: - | E15: - | F15: 30.000 (Otuz bin) TL | G15: Söz konusu personel sahadan uzaklaştırılır.
A16: 26.10. | B16: YEDAŞ’ın yapacağı denetimlere ve numune alma işlemine YÜKLENİCİ tarafından engel olunması | D16: - | E16: 7 Gün | F16: İş durdurulur | G16: Bu durumun ortadan kaldırılmaması halinde YÜKLENİCİ’nin kesin teminatı irat kaydedilerek Sözleşme feshedilebilir.
A17: 26.11. | B17: YÜKLENİCİ’nin tedarik ettiği malzemeleri YEDAŞ’a bildirmemesi halinde | D17: - | E17: - | F17: Sözleşme bedelinin %1’i (Yüzde Bir) | G17: Tespit sayısının 10 adeti aşması halinde YÜKLENİCİ’nin kesin teminatı irat kaydedilerek Sözleşme feshedilebilir.
A18: 26.12. | B18: Ayıplı/uygunsuz malzeme kullandığı tespit edilmesi halinde | D18: - | E18: 5 Gün | F18: Sözleşme bedelinin %0,1 (Binde Bir) | G18: Gecikilen günün 10 (On) günü aşması halinde ayıplı/uygunsuz malzemenin demontaj edilemeyecek durumda olduğu kabul edilir ve Sözleşme’nin 33.1.j maddesi çerçevesinde kesin teminat ve varsa ek kesin teminatlar gelir kaydedilir ve sözleşme feshedilerek hesabı sözleşmenin ilgili maddelerine göre tasfiye edilir.
A19: 26.15. | B19: YÜKLENİCİ nin iş kanunu ve sair mevzuat hükümlerine aykırı davranmasını tespit etmesi yahut buna ilişkin şikayet olması halinde | D19: - | E19: 7 Gün | F19: 30.000 (Otuz bin) TL | G19: Söz konusu aykırılığının giderilmesi için yükleniciye bir hafta süre verilir.
A20: 32.1.2. | B20: Yer teslim talebinde bulunulmaması durumunda | D20: - | E20: - | F20: Sözleşme feshi ve YEDAŞ'ın uğradığı tüm zararların karşılanması. | G20: Yüklenicinin 5 (Beş) gün içerisinde yer teslimi talebinde bulunmaması halinde, 5 (Beş) günü takip eden 10 (On) gün içerisinde, YEDAŞ tarafından resen belirlenecek bir tarihte, Yüklenici yer teslimine davet edilecektir. Yüklenici saptanan günde yer teslimi yapılacak mahalde bulunmaz veya noterlikçe yetkili kılınmış teknik vekilini bulundurmazsa

Sheet Özet(YEDAŞ2025)
A2: Özel Hükümler Madde | B2: Özel Hükümler | C2: Genel Hükümler Madde | D2: Genel Hükümler | E2: İçerik | F2: Yüklenici Sorumluluğu | G2: Yüklenici Sorumluluğu | H2: İçerik | I2: Yüklenicinin sorumluluğu | J2: Cezai Durum | K2: FESİH | L2: GENEL ŞARTNAME
A3: Madde 1 | B3: Konu ve Bütünlük | E3: Sözleşmenin taraflarını içeriyor.
A4: Madde 2 | B4: Taraflara İlişkin Bilgiler | E4: Taraflara ait bilgileri içeriyor.
A5: Madde 3 | B5: Tanımlar | E5: İşin adını, yapılma yerini, niteliğini, türünü ve miktarını içeriyor.
A6: Madde 4 | B6: Yüklenicinin Sorumluluğu | C6: Madde 12 | D6: Yüklenicinin Sorumluluğu | E6: Sözleşme kapsamında yapılan çalışmalarda mevzuata ve sözleşmeye uyacağını kabul eder | F6: İSG-ç'ye uygun davranacak | G6: Yüklenici tarafından kullanılacak araçlar işin yapımına uygun, işçi sağlığına ris oluşturmayacak araçları temin edecek. | H6: Yüklenici de işin süresi boyunca Özel Hükümler 13. maddesinde yer alan yapılanmayı oluşturmakla yükümlüdür. Yüklenici, YEDAŞ Bakım Proje Yönetimi ile koordineli olacak şekilde oluşturacağı bu yapılanmadaki Elektrik Mühendisi unvanlı Şantiye Şefini YEDAŞ’ a bildirir. | I6: YÜKLENİCİ üstlenmiş olduğu işin fen ve sanat kurallarına uygun olarak yapılmaması, hileli malzeme kullanılması ve benzeri nedenlerle ortaya çıkan zarar ve ziyan bakımından işin tamamından işe başlama tarihinden kesin kabul tarihine kadar sorumludur . | K6: 18.3. sözleşme eki ve taahhütlerini yerine hetirmediği tespit edilirse feshedilir.
A7: Madde 5 | B7: Kontrol Teşikilatı ve Denetim | E7: İşin uygun yürütülüp yürütülmediği YEDAŞ tarafından her zaman kontrol edebilir | F7: Yüklenici denetim esnasında her türlü desteği ve kolaylığı sağlayacak. | K7: Aykırı durumda sözleşme feshedilir. | L7: MADDE 14:Sözleşmeye bağlanan her türlü bakım onarım işleri, YEDAŞ tarafından görevlendirilen proje yönetim personelinin denetimi altında, Yüklenici tarafından yönetilir ve gerçekleştirilir.
A8: Madde 6 | B8: Süre Uzatımı Verilebilecek Haller ve Şartlar | E8: Mücbir sebepler ve YEDAŞ'tan kaynaklanan nedenlerle süre uzatımı verilme durumu.
A9: Madde 7 | B9: YÜKLENİCİ’nin Ölümü, İflası, Ağır Hastalığı, Tutukluluğu veya Mahkûmiyeti | K9: Sözleşme Feshedilebilir. | L9: Madde 27 - İşin, sözleşmesinde belirlenen zamanda tamamlanıp geçici kabule hazır hale getirilmemesi durumunda, gecikilen her günü için sözleşmesinde öngörülen gecikme cezası uygulanır. Sözleşmesinde belirtilen mücbir sebepler ve/veya YEDAŞ’ın sebep olduğu hallerden dolayı, işte sorumluluğu yükleniciye ait olmayan gecikmelerin meydana gelmesi halinde, durum YEDAŞ tarafından incelenerek işi engelleyici sebeplere ve yapılacak işin niteliğine göre işin bir kısmına veya tamamına ait süre uzatılır.
A10: Madde 8 | B10: Yüklenicinin sözleşme konusu iş ile ilgili çalıştıracağı personele ilişkin sorumlulukları | E10: SGK'ya bildirimde bulunacak. Vergi borcu sgk borcu personel borcu olmayacak
A11: Madde 9 | B11: İşin devamı sırasında dikkat edilecek hususlar, yürütülmesine ilişkin kayıt, tutanaklar, hak ediş ve kesin hesapların yapılması | E11: Hakedişlerin düzenlenmesi ve hakedişle birlikte teslim edilmesi gereken evraklar | F11: Tesis çizimleri , malzeme mutabakat formu, Enerjilendirme protokolleri vb diğer evraklar. | J11: Hakediş onaylanmaz. | L11: Madde 33 - Geçici hakediş raporları Yüklenicinin başvurusu üzerine, sözleşme veya eklerinde aksine bir hüküm bulunmadıkça aylık periyotlar halinde [ 30(Otuz) günde bir] düzenlenir. Gelecek yıllara sari olmayan sözleşmelerde yaptırılan işler için, son hakediş raporu bütçe yılının sonuna rastlayan ayın 20(Yirmi)’nci günü düzenlenir.
A12: Madde 11 | B12: İşin ve işyerlerinin korunması ve sigortalanması | E12: Her türlü araç, malzeme, iş ve hizmet makine, taşıtların sigortalanması | F12: All Risk Sigortası ve Mali mesuliyet Sigortası Yaptırmakla Yükümlüdür. | L12: MADDE-9 SÖZLEŞMEYE GÖRE GERÇEKLEŞTİRİLİK
A13: Madde 12 | B13: Yer Teslimi | C13: Madde 6 | D13: Sözşmenin Başlangıç süresi işe başlama ve bitirme tarihleri | E13: Yer teslimi talebi ve onaylanmasını içeren madde | F13: 5 gün içerisinde yer teslimi talebinde bulunur ve 10 gün içerisinde yer teslimi yapılır ve onaylanır. Yer tesliminin onaylanması durumda iş programı düzenlenir. | G13: Yer teslimi onaylanma tarihi işe başlama tarihi olarak belirlenir ve İSG-Ç gereksinimlerini yerine getirmekle yükümlüdür. | H13: Sözleşmenin Başlangıcı, Süresi, İşe başlama ve bitirme tarihi | I13: 5 gün içinde yer teslimi talebinde bulunulur ve 10 gün içerisinde yer teslimi yapılır | J13: YEDAŞ’ nin uğradığı tüm zararlar Yüklenici alacakları ve teminatlarından karşılanır. | K13: 5 gün içerisinde yer teslim talebinde bulunmaması durumunda 10 gün içinde ihtar çekilip yer teslimine katılması istenir. 2.defa katılmaması durumunda fesih | L13: Sözleşmesinin imzalanmasından sonra Yüklenicinin sözleşmede yazılı süre içinde işe başlayabilmesi için işyeri, ihale esas proje ve mahal listesine göre; eksen kazıkları, someler, röperler vb., proje sahası, güzergah, zemin veya buna benzer yerler üzerinde kontrol edilerek YEDAŞ tarafından görevlendirilen proje yönetim personeli tarafından Yükleniciye teslim edilir ve yer teslim tutanağı düzenlenir.
A14: Madde 12 | B14: İş Programı | C14: Madde 6 | D14: Sözşmenin Başlangıç süresi işe başlama ve bitirme tarihleri | E14: İş programının yapılmasına dair madde | F14: Yer tesliminin onaylanmasından itibaren 5 gün içerisinde iş programı hazırlanır ve 5 gün içerisimde YEDAŞ gerekli düzenlemeleri yaparak onaylar. | G14: 31.08.2026 tarihinde sahadaki fiziki iş bitilecek. | H14: Sözleşmenin Başlangıcı, Süresi, İşe başlama ve bitirme tarihi | I14: YEDAŞ’ ın işin Yüklenici ekip ve araç/gereç eksikliğinden dolayı iş programına göre yavaş ilerlediğini tespit etmesi ve gerek görmesi halinde, Yüklenici ekip ve ekipman sayısını artıracaktır. Yüklenici bünyesinde yapacağı bu ekip ve ekipman artışından dolayı YEDAŞ’ tan fiyat farkı talep etmeyecektir. İşin süresinde bitirilmesi halinde Bakım Onarım İşleri Genel Şartnamesi hükümleri doğrultusunda kabul işlemleri yapılacaktır. | J14: İş programında imzaya imtina etmesi ve düzenlemesini geciktirmesi durumunda 150bin tl,Yüklenici yer teslim verilen ve aylık iş programında yer alan projeleri aylık iş programında belirtilen sürelerde tamamlamak zorundadır. Yüklenici kaynaklı nedenlerden dolayı aylık iş programında belirtilen sürelerde tamalanamayan projeler bir sonraki iş programına eklenir. Bir sonraki iş programında da bitirilmediği tespit edilirse bitirilmeyen her bir proje için proje bedelinin %10’u(yüzde on) oranında cezai işlem uygulanır. | K14: 18.2. iş planına uyulmaz ve işi süresi içerisinde bitiremeyeceği anlaşılırsa sözleşme feshedilir | L14: Yüklenici, yer tesliminin yapıldığı tarihten itibaren sözleşme veya eklerinde belirlenen süre içinde, YEDAŞ tarafından verilen örneklere uygun ve sözleşmede belirtilen iş kısımları ve bitirme tarihleri ile yıllık finansman miktarlarını da dikkate alarak hazırlayacağı; iş kalemlerini, iş gruplarını, aylık imalatı ve iş miktarlarını, (ihzarat ödemesi öngörülen birim fiyat esaslı işlerde ihzaratı), yıllık finansman dilimlerini ve bunların aylara dağılımını gösterir ayrıntılı iş programlarını (en az iki nüsha) hazırlayarak onaylanmak üzere YEDAŞ’a teslim edecektir.
A15: Madde 13 | B15: Teknik personel ve Sepetli Araç bulundurulması | C15: Madde 12 | D15: Yüklenicinin sorumluluğu | E15: Yüklenicinin saha operasyonunu belirtiyor. | F15: 1 adet şantiye şefi ve 1 adet saha mühendisi olmak üzere en az 2 mühendis. Ayrıca her ekip için birer adet elektrik-elektronik mühn- veya teknikeri bulundurmak zorundadır.Tam zamanlı görevlendirilmek üzere en az C sınıfı İSG uzmanı | G15: Bu mühendisler başka sözleşme kapsamında veya başka işte kullanıkmayacaktır. | H15: Yüklenici de işin süresi boyunca Özel Hükümler 13. maddesinde yer alan yapılanmayı oluşturmakla yükümlüdür. | I15: Belirtilen Anahtar Teknik personel; işin yürütülmesi ile ilgili iş vereni pozisyonunda bulunan YEDAŞ yetkili sıralı amirlerine (Bölge Saha Kontrol Uzmanı, Genel Müdürlük Bölge Sözleşme Yöneticisi Bakım Uzmanı, Bakım Onarım Şefi, Müdür) karşı yükümlüdür. Anahtar teknik personel; iş ahlakına uygun, gelişmiş iletişim teknikleri becerisine sahip ve toplumsal kurallara saygılı ve YEDAŞ kurumsal kültürüne uygun davranacaktır. Sözleşmenin yürütülebilmesi için görevlerini ihmal etmeyecek ve ettiği durumlarda oluşabilecek zarar ve ziyandan YEDAŞ sorumlu olmayacaktır. Bahse konu hususlara riayet edilmemesi durumunda YEDAŞ 7 Gün içinde yapacağı ihtar üzerine anahtar teknik personelin görevine sözleşme kapsamında devam edilemeyeceğini talep edebilir | J15: her bi teknik personel için 30 günü aşmamak kaydıyla günlük 10 bin tl ceza uygulkanır | L15: Madde 19 - Yüklenicinin üstlenmiş olduğu işin devamı süresince, iş yerinde bulunması esastır. Bununla birlikte, Yüklenici işlerin gecikmesine ve durmasına yol açmamak şartı ile noterce düzenlenmiş bir vekaletnameyle tam yetki almış ve YEDAŞ tarafından kabul edilmiş bir vekil bırakarak iş başından ayrılabilir. Yüklenici veya vekili iş yerinden ayrılmalarını gerektiren hallerde, proje yönetim personelinden izin almak zorundadır.
A16: Madde 13 | B16: Teknik personel ve Sepetli Araç bulundurulması | C16: Madde 15 | D16: Genel Hükümler | E16: Sepetli araç bulundurma şartı ile ilgili madde | F16: en az bir adet sepetli araç bulundurmak zorunda. | G16: talepten bağımsız olarak işin niteliğine göre sayının yetmemesi durumunda talepten bağımsız olarak sepetli araç bulundurmak zorunda | H16: . YÜKLENİCİ, taahhüt ettiği hizmeti ve bu hizmete ilişkin her türlü personel, ekip ekipman, teçhizat, makine, malzeme, araç ve gereç ile nakliye vb. gibi unsurları sağlamak temin etmek zorundadır. | I16: YÜKLENİCİ tarafından işin yapımında kullanılacak tüm araçlarda araç içi, önü ve arkasını kapsayacak şekilde ilgili teknik şartnameye uygun 3’lü kamera sistemi bulundurulacaktır. | L16: Madde 19 - Yüklenici, işin sözleşme süresi içinde bitirilmesi için, gerekli miktarda malzemeyi ve yeterli sayıda işçiyi her an iş başında bulunduracaktır. Aksi halde, bu hususta kendisini uyarmak üzere yapılacak tebligat tarihinden başlamak üzere on gün içinde bunları istenen sayıya ve miktara tamamlamak zorundadır.
A17: Madde 14 | B17: Kabul Edilmeyen İşler | E17: Yüklenici tarafından tedarik edilen malzemlerin uygunluğunun kontrolü ile ilgili madde | F17: Uygunsuz hatalı malzemelerin değiştirilmesi bunlar için ödenen bedelleri geri istenebilir | K17: 18.5.Haciz kaldırılmazsa Feshedilir.
A18: Madde 15 | B18: Teslim, muayene ve kabul işlemlerine ilişkin şartlar | E18: Malzeme kabul heyeti oluşturulacak. | J18: Ayıplı/uygunsuz malzemelerin kullanılması durumunda ödemeler askıya alınır v uygunsuzluğun giderilmemesi durumunda sözleşme feshedilir. | L18: Proje yönetim personeli, Yüklenici tarafından yapılmış olan işin eksik, hatalı ve kusurlu olduğunu veya malzemenin şartnamesine uygun olmadığını gösteren delil ve emareler gördüğü takdirde, gerek işin yapımı sırasında ve gerekse kesin kabule kadar olan sürede bu gibi eksiklerin, hataların ve kusurların incelenmesi ve tespiti için gerekli görülen yerlerin kazılmasını ve/veya yıkılıp yeniden yapılmasını Yükleniciye tebliğ eder.
A19: Madde 16 | B19: Montaj, işletmeye alma, eğitim, bakım onarım, yedek parça gibi destek hizmetlerine ait şartlar | E19: Tesis enerjilendirildiği tarihte enerjilendirme tutanağı tutulmalı | F19: Teshis enerjilendirilmeden yapılan kontrollerde enerjilendirilmesine engel durumlar ortadan kaldırılmadan tesis enerjilendirilmeyecek. | J19: Tesis uygun duruma getirilip enerjilendirildiği süreye göre cezai işlem uygulanır.
A20: Madde 17 | B20: Sorumluluk Alanı ve Bölgeler Arası Çalışma | E20: Diğer il ve ilçelerde yüklenici görevlendirilebilir. | F20: Acil iş kapsamında verilen işleri öncelikli olarak yapacaktır.
A21: Madde 18 | B21: Proje Yönetimine ilişkin şartlar | E21: İşler fen ve sanat kurallarına uygun olarak yapılmasını belirten madde. | F21: Projede risk teşkil eden etken ve gereksinimleri tespit ederek gerekli önlemlerin alıması konusunda YEDAŞ'a raporlar.
A22: Madde 19 | B22: Projeler | E22: elektrik tesis proje yönetmeliği ve proje onayına ilişkin usul ve esaslara göre projeler düzenlenecektir. | F22: Projeler için ayrıca bir bedel ödenmeyecektir. | G22: KEYPOS isterleri yerine getirilecektir. Projeler ile ilgili her türlü bilgi belge YEDAŞ'a teslim edilecek. | J22: 17.7.Sahada tamamlanan işlerin 15 gün içerisinde son durum projelerinin getirilmemesi durumunda proje bedelinin %0,5(binde beş) oranında ceza uygulanır. Projeler yıl sonunda teslim edilmez ise yüzde 3'lük teminat kesintisi yapılır. | L22: MADDE 11 :Anahtar teslimi götürü bedel sözleşmelerde, yapılacak işlerin uygulama projeleri, şartnameler ve diğer teknik belgeler birlikte sözleşme hükümleri çerçevesinde yürütülür. MADDE 12 : Yüklenicinin yapacağı uygulama projeleri, hesaplar vb. sözleşme ve eklerinde belirtilen şartlara, talimatlara, esaslara, fen ve sanat kurallarına uygun olarak iş programını aksatmayacak şekilde hazırlanır ve uygulamada gerekli görülecek tüm ölçüleri ve ayrıntıları kapsar.
A23: Madde 20 | B23: Malzemelerin Taşınma, Muhafaza ve İadesi | E23: YEDAŞ tarafından verilen malzemelerin ve sahadan sökülen malzemelerin eksiksiz olarak geri getirilmesini içerir madde. | F23: Kesin ölçümler sonucu kalan malzemeyi YEDAŞ ambarlarına teslim edilmesi | J23: Malzeme mutabakatı sonrasında deposunda kalan malzemelerin iadesini gerçekleştirmezse güncel bedeller üzerinden mahsup edilir. İşin devamı sırasında malzemenin başka bir tesiste kullanıldığı anlaşılırsa teminatlarından güncel malzeme bedeli kesilir.
A24: Madde 21 | B24: Geçici ve Kesin Kabul ile Tespitler | E24: Geçici kabul ve kesin kabul işlemleri elektrik tesisleri kabul yönetmeliğine ve diğer mevzuat hükümlerince yapılır. | F24: Tesise ait resimler topraklama ölçümleri …vb YEDAŞ'a teslim edilecektir. | J24: Aksi takdirde başkaca bir ihtara gerek kalmaksızın, proje hakediş bedelinin %3 ü kesilecektir | L24: Madde 33- Geçici Hakediş Raporları : Yüklenicinin yaptığı işler, metrajlara göre hesaplanarak sözleşme hükümleri uyarınca kesin ödeme niteliğinde olmamak ve kazanılmış hak sayılmamak üzere geçici hakediş raporları ile ödenir. Metrajlar, yeşil defter ve eklerinde gösterilir.Yüklenici, YEDAŞ’ın isteği halinde, kesin hesapları da proje yönetim personelinin denetimi altında işe paralel olarak yürütmek zorundadır. Bu halde, geçici hakediş raporlarının düzenlenmesinde, bitmiş iş kısımları için kesin metrajdaki miktarlar dikkate alınır.
A25: Madde 22 | B25: Sözleşmenin İmzalanması
C26: Madde 3 | D26: Sözleşmenin türü ve bedeli | E26: anahtar teslim biri fiyatlı eser sözleşme | F26: 2025 yılı TEDAŞ birim fiyat kitabı ve YEDAŞ tarafından oluşturulmuş birim fiyatlar üzerinden uygulanacaktır.
C27: Madde 7 | D27: Teminatlara ilişkin hükümler-Kesin teminat | H27: Kesin teminat tl cinsinden verilirse %10USD ve EURO olarak mektup şeklinde verilmesi durumunda %6, Euro ve Dolar cinsinden nakit olarak verilmesi durumunda %5 i olmak üzere 4 yıl süreli | I27: Kesin kabullerin yapılmış ve hiçbir hukuki sürecinin bulunmaması durumunda 4 yıl sonunda geri verilir. | J27: 17.3.2.teminat yükümlülüklerini yerine getirmemesi halinde, allacaklarından yapılan bloke ile teminat alınır, karşılamıyorsa binde 1 oranında ceza
C28: Madde 7 | D28: Teminatlara ilişkin hükümler-Malzeme Teminatı | H28: Sözleşme bedelinin %10'u olmak üzere 15 aylık | I28: Kesin hakediş ve malzeme mutabakatı yapıldıktan sonra iade edilr.
C29: Madde 8 | D29: Ödeme yeri ve şartları | H29: faturanın %50si 20.günde %50'si 40.günde | I29: hakediş raporu ile birlikte YEDAŞ'ın talep ettiği evrakları getirmekle yükümlüdür.
C30: Madde 9 | D30: Avans verilmesi | H30: Avans verilmeyecek
C31: Madde 10 | D31: Fiyat farkı ödenmesi | H31: Fiyat farkı ödenmeyecek | I31: Güvenli çalışma performansı fiyat farkı değerlendirilmesi kapsamında İSG performansına göre +-%1 oranında sözleşme bedeli üzerinden değerlendirilecek
C32: Madde 11 | D32: Alt yüklenici ve sözleşmeninn devri yasağı | H32: Alt yüklenici çalıştıramaz, sözleşme devri yapılamaz | J32: 17.4. aykırı durumda söz konusu ise %5 ceza | K32: 18.5.1. yerine getirmemesi durumunda sözleşme feshedilir.
C33: Madde 12 | D33: Yüklenicinin sorumluluğu | H33: Belirli sayıda mühendis ve taknik personel bulunduracak, Malzeme tedariği yapacağı,
C34: Madde 13 | D34: İş eksiltme İlave İş verme | H34: %25 ile sınırlıdır.
C35: Madde 14 | D35: Hükmü bulunamayan haller
C36: Madde 15 | D36: Genel Hükümler | H36: İstenildiği taktirde findeks…vs verecek | I36: HER TÜRLÜ BİLİGİ BELGELERİ ALMAK VE yedaş'A TESLİM ETMEKLE YÜKÜMLÜ | J36: 17.8 YEDAŞ'a sunması gereken bilgi belgeleri sunmadığı durumda sözleşme bedelinin binde 1 oranında ceza kesilir
C37: Madde 16 | D37: Yüklenicinin ölümü iflası ağır hastlığı tutukluluk veya mahkumiyeti | H37: %50 ortak ölürse veya iflas ederse sözleşme feshedilir
C38: Madde 17 | D38: Cezai Hükümler | H38: Kesilecek gecikme cezaları ayrıca protesto çekmeye gerek kalmaksızın kesilebilir.
C39: Madde 17 | D39: Cezai Hükümler | H39: Kesilecek cezaların üst limiti %10
C40: Madde 17.6. | D40: Cezai Hükümler | J40: 3.şahıslara bilgi belge verilmesi durumunda %1
C41: Madde 17.10 | D41: Cezai Hükümler | J41: uygun şantiye alanı bildirmemesi durumunda 250bin tl
...

Sheet Formül
A3: Sözleşme imzalandı | B3: 46059 | C3: Gün | E3: Sözleşme imzalandı | F3: Yer teslimi talebi yapılır | G3: Yer teslimi yapılır | H3: Yer teslimi onaylanır | I3: İş programı hazırlanır
A4: Yer teslimi talebi yapılır | B4: =B3+5 -> 46064 | C4: Gün | E4: 45023 | F4: =E4+5 -> 45028 | G4: =F4+15 -> 45043 | H4: =G4+5 -> 45048 | I4: =H4+10 -> 45058
A5: Yer teslimi yapılır ve onaylanır | B5: =B4+10 -> 46074 | C5: Gün
A6: İş programı hazırlanır ve onaylanır | B6: =B5+10 -> 46084 | C6: Gün
A7: İş programı onaylanır | B7: =B6+5 -> 46089 | C7: Gün
A8: 1.Hk. | B8: 46096 | C8: Gün
A9: 1.Hk. | B9: =B8+30 -> 46126 | C9: Gün
A10: 2.Hk. | B10: =B9+30 -> 46156 | C10: Gün
A11: 3.Hk. | B11: =B10+31 -> 46187 | C11: Gün
A12: 4.Hk. | B12: =B11+31 -> 46218 | C12: Gün
A13: 5.Hk ve Geçici Kabule Hazırlanması | B13: =B12+45 -> 46263 | C13: Gün
A14: Geçici Kabul yapılası ve eksikliklerin giderilmesi | B14: =B13+30 -> 46293 | C14: Gün
A15: Kesin Hakediş | B15: =B14+30 -> 46323 | C15: Gün

Sheet PROJE SAYILARI
I1: TESİS ŞARTNAMESİ | M1: BAKIM ŞARTNAMESİ(1.SENARYO) | Q1: BAKIM ŞARTNAMESİ(2.SENARYO) | U1: BAKIM ŞARTNAMESİ(3.SENARYO)
A2: GRUP | B2: GELİR | C2: İHALE | D2: DİREK | E2: PROJE SAYISI | F2: PROJE BAŞINA DÜŞEN DİREK SAYILARI | H2: EKİP SAYISI | I2: ŞANTİYE ŞEFİ | J2: KOORDİNATÖR MÜH | K2: EKİP AMİRİ | L2: İSG UZMANI | M2: ŞANTİYE ŞEFİ | N2: KOORDİNATÖR MÜH | O2: EKİP AMİRİ | P2: İSG UZMANI | Q2: ŞANTİYE ŞEFİ | R2: KOORDİNATÖR MÜH | S2: EKİP AMİRİ | T2: İSG UZMANI | U2: ŞANTİYE ŞEFİ | V2: EKİP YÖNETİMİ | W2: İSG UZMANI
A3: AMASYA MERKEZ BAKIM | B3: 1.5128072e+08 | C3: 46786208 | D3: 628 | E3: =_xlfn.XLOOKUP(A3,$AC$3:$AC$23,$AD$3:$AD$23) -> 44 | F3: =D3/E3 -> 14.272727 | G3: =D3/$AB$4 -> 0.70960452 | H3: =ROUND(G3/0.7,0) -> 1 | I3: 1 | J3: 1 | K3: 3 | L3: 1 | M3: 1 | N3: 1 | O3: =H3 -> 1 | P3: 1 | Q3: 1 | S3: =H3 -> 1 | T3: =S3 -> 1 | U3: 1 | V3: =H3 -> 1 | W3: 1 | Y3: 46068 | Z3: 46265 | AA3: =Z3-Y3 -> 197 | AB3: =AA3-20 -> 177 | AC3: AMASYA MERKEZ BAKIM | AD3: 44
A4: MERZİFON BAKIM | B4: 1.55885e+08 | C4: 48519718 | D4: 844 | E4: =_xlfn.XLOOKUP(A4,$AC$3:$AC$23,$AD$3:$AD$23) -> 96 | F4: =D4/E4 -> 8.7916667 | G4: =D4/$AB$4 -> 0.95367232 | H4: =ROUND(G4/0.7,0) -> 1 | I4: 1 | J4: 1 | K4: 3 | L4: 1 | M4: 1 | N4: 1 | O4: =H4 -> 1 | P4: 1 | Q4: 1 | S4: =H4 -> 1 | T4: =S4 -> 1 | U4: 1 | V4: =H4 -> 1 | W4: 1 | AB4: =5*AB3 -> 885 | AC4: AYANCIK BAKIM | AD4: 55
A5: ÇORUM MERKEZ BAKIM | B5: 2.3939803e+08 | C5: 75056995 | D5: 1550 | E5: =_xlfn.XLOOKUP(A5,$AC$3:$AC$23,$AD$3:$AD$23) -> 57 | F5: =D5/E5 -> 27.192982 | G5: =D5/$AB$4 -> 1.7514124 | H5: =ROUND(G5/0.7,0) -> 3 | I5: 1 | J5: 1 | K5: 3 | L5: 1 | M5: 1 | N5: 1 | O5: =H5 -> 3 | P5: 1 | Q5: 1 | R5: 1 | S5: =H5 -> 3 | T5: =S5 -> 3 | U5: 1 | V5: =H5 -> 3 | W5: 1 | AC5: BAFRA BAKIM | AD5: 45
A6: SUNGURLU BAKIM | B6: 1.7092747e+08 | C6: 53589863 | D6: 1081 | E6: =_xlfn.XLOOKUP(A6,$AC$3:$AC$23,$AD$3:$AD$23) -> 29 | F6: =D6/E6 -> 37.275862 | G6: =D6/$AB$4 -> 1.2214689 | H6: =ROUND(G6/0.7,0) -> 2 | I6: 1 | J6: 1 | K6: 3 | L6: 1 | M6: 1 | N6: 1 | O6: =H6 -> 2 | P6: 1 | Q6: 1 | R6: 1 | S6: =H6 -> 2 | T6: =S6 -> 2 | U6: 1 | V6: =H6 -> 2 | W6: 1 | AC6: BOYABAT BAKIM | AD6: 42
A7: OSMANCIK BAKIM | B7: 1.6980158e+08 | C7: 53737196 | D7: 1001 | E7: =_xlfn.XLOOKUP(A7,$AC$3:$AC$23,$AD$3:$AD$23) -> 31 | F7: =D7/E7 -> 32.290323 | G7: =D7/$AB$4 -> 1.1310734 | H7: =ROUND(G7/0.7,0) -> 2 | I7: 1 | J7: 1 | K7: 3 | L7: 1 | M7: 1 | N7: 1 | O7: =H7 -> 2 | P7: 1 | Q7: 1 | R7: 1 | S7: =H7 -> 2 | T7: =S7 -> 2 | U7: 1 | V7: =H7 -> 2 | W7: 1 | AC7: ÇARŞAMBA BAKIM | AD7: 49
A8: İSKİLİP BAKIM | B8: 2.174772e+08 | C8: 67974087 | D8: 1466 | E8: =_xlfn.XLOOKUP(A8,$AC$3:$AC$23,$AD$3:$AD$23) -> 50 | F8: =D8/E8 -> 29.32 | G8: =D8/$AB$4 -> 1.6564972 | H8: =ROUND(G8/0.7,0) -> 2 | I8: 1 | J8: 1 | K8: 3 | L8: 1 | M8: 1 | N8: 1 | O8: =H8 -> 2 | P8: 1 | Q8: 1 | R8: 1 | S8: =H8 -> 2 | T8: =S8 -> 2 | U8: 1 | V8: =H8 -> 2 | W8: 1 | AC8: ÇORUM MERKEZ BAKIM | AD8: 57
A9: ÜNYE BAKIM | B9: 2.0233566e+08 | C9: 67589798 | D9: 1205 | E9: =_xlfn.XLOOKUP(A9,$AC$3:$AC$23,$AD$3:$AD$23) -> 48 | F9: =D9/E9 -> 25.104167 | G9: =D9/$AB$4 -> 1.3615819 | H9: =ROUND(G9/0.7,0) -> 2 | I9: 1 | J9: 1 | K9: 3 | L9: 1 | M9: 1 | N9: 1 | O9: =H9 -> 2 | P9: 1 | Q9: 1 | R9: 1 | S9: =H9 -> 2 | T9: =S9 -> 2 | U9: 1 | V9: =H9 -> 2 | W9: 1 | AC9: FATSA BAKIM | AD9: 34
A10: ORDU MERKEZ BAKIM | B10: 2.6470225e+08 | C10: 85561943 | D10: 1816 | E10: =_xlfn.XLOOKUP(A10,$AC$3:$AC$23,$AD$3:$AD$23) -> 90 | F10: =D10/E10 -> 20.177778 | G10: =D10/$AB$4 -> 2.0519774 | H10: =ROUND(G10/0.7,0) -> 3 | I10: 1 | J10: 1 | K10: 3 | L10: 1 | M10: 1 | N10: 1 | O10: =H10 -> 3 | P10: 1 | Q10: 1 | R10: 1 | S10: =H10 -> 3 | T10: =S10 -> 3 | U10: 1 | V10: =H10 -> 3 | W10: 1 | AC10: GÖLKÖY BAKIM | AD10: 50
A11: FATSA BAKIM | B11: 1.5310157e+08 | C11: 51953409 | D11: 865 | E11: =_xlfn.XLOOKUP(A11,$AC$3:$AC$23,$AD$3:$AD$23) -> 34 | F11: =D11/E11 -> 25.441176 | G11: =D11/$AB$4 -> 0.97740113 | H11: =ROUND(G11/0.7,0) -> 1 | I11: 1 | J11: 1 | K11: 3 | L11: 1 | M11: 1 | N11: 1 | O11: =H11 -> 1 | P11: 1 | Q11: 1 | S11: =H11 -> 1 | T11: =S11 -> 1 | U11: 1 | V11: =H11 -> 1 | W11: 1 | AC11: HAVZA BAKIM | AD11: 47
A12: KORGAN BAKIM | B12: 1.6191048e+08 | C12: 54673702 | D12: 1105 | E12: =_xlfn.XLOOKUP(A12,$AC$3:$AC$23,$AD$3:$AD$23) -> 39 | F12: =D12/E12 -> 28.333333 | G12: =D12/$AB$4 -> 1.2485876 | H12: =ROUND(G12/0.7,0) -> 2 | I12: 1 | J12: 1 | K12: 3 | L12: 1 | M12: 1 | N12: 1 | O12: =H12 -> 2 | P12: 1 | Q12: 1 | R12: 1 | S12: =H12 -> 2 | T12: =S12 -> 2 | U12: 1 | V12: =H12 -> 2 | W12: 1 | AC12: İLKADIM BAKIM | AD12: 60
A13: GÖLKÖY BAKIM | B13: 2.4040377e+08 | C13: 74740216 | D13: 1659 | E13: =_xlfn.XLOOKUP(A13,$AC$3:$AC$23,$AD$3:$AD$23) -> 50 | F13: =D13/E13 -> 33.18 | G13: =D13/$AB$4 -> 1.8745763 | H13: =ROUND(G13/0.7,0) -> 3 | I13: 1 | J13: 1 | K13: 3 | L13: 1 | M13: 1 | N13: 1 | O13: =H13 -> 3 | P13: 1 | Q13: 1 | R13: 1 | S13: =H13 -> 3 | T13: =S13 -> 3 | U13: 1 | V13: =H13 -> 3 | W13: 1 | AC13: İSKİLİP BAKIM | AD13: 50
A14: İLKADIM BAKIM | B14: 1.4061398e+08 | C14: 47619810 | D14: 925 | E14: =_xlfn.XLOOKUP(A14,$AC$3:$AC$23,$AD$3:$AD$23) -> 60 | F14: =D14/E14 -> 15.416667 | G14: =D14/$AB$4 -> 1.0451977 | H14: =ROUND(G14/0.7,0) -> 1 | I14: 1 | J14: 1 | K14: 3 | L14: 1 | M14: 1 | N14: 1 | O14: =H14 -> 1 | P14: 1 | Q14: 1 | S14: =H14 -> 1 | T14: =S14 -> 1 | U14: 1 | V14: =H14 -> 1 | W14: 1 | AC14: KORGAN BAKIM | AD14: 39
A15: BAFRA BAKIM | B15: 1.712905e+08 | C15: 51594784 | D15: 940 | E15: =_xlfn.XLOOKUP(A15,$AC$3:$AC$23,$AD$3:$AD$23) -> 45 | F15: =D15/E15 -> 20.888889 | G15: =D15/$AB$4 -> 1.0621469 | H15: =ROUND(G15/0.7,0) -> 2 | I15: 1 | J15: 1 | K15: 3 | L15: 1 | M15: 1 | N15: 1 | O15: =H15 -> 2 | P15: 1 | Q15: 1 | R15: 1 | S15: =H15 -> 2 | T15: =S15 -> 2 | U15: 1 | V15: =H15 -> 2 | W15: 1 | AC15: MERZİFON BAKIM | AD15: 96
A16: ÇARŞAMBA BAKIM | B16: 1.5899922e+08 | C16: 49224108 | D16: 914 | E16: =_xlfn.XLOOKUP(A16,$AC$3:$AC$23,$AD$3:$AD$23) -> 49 | F16: =D16/E16 -> 18.653061 | G16: =D16/$AB$4 -> 1.0327684 | H16: =ROUND(G16/0.7,0) -> 1 | I16: 1 | J16: 1 | K16: 3 | L16: 1 | M16: 1 | N16: 1 | O16: =H16 -> 1 | P16: 1 | Q16: 1 | S16: =H16 -> 1 | T16: =S16 -> 1 | U16: 1 | V16: =H16 -> 1 | W16: 1 | AC16: ORDU MERKEZ BAKIM | AD16: 90
A17: HAVZA BAKIM | B17: 2.5024425e+08 | C17: 80424373 | D17: 1709 | E17: =_xlfn.XLOOKUP(A17,$AC$3:$AC$23,$AD$3:$AD$23) -> 47 | F17: =D17/E17 -> 36.361702 | G17: =D17/$AB$4 -> 1.9310734 | H17: =ROUND(G17/0.7,0) -> 3 | I17: 1 | J17: 1 | K17: 3 | L17: 1 | M17: 1 | N17: 1 | O17: =H17 -> 3 | P17: 1 | Q17: 1 | R17: 1 | S17: =H17 -> 3 | T17: =S17 -> 3 | U17: 1 | V17: =H17 -> 3 | W17: 1 | AC17: OSMANCIK BAKIM | AD17: 31
A18: SAMSUN MERKEZ BAKIM | B18: 1.5384075e+08 | C18: 47465110 | D18: 892 | E18: =_xlfn.XLOOKUP(A18,$AC$3:$AC$23,$AD$3:$AD$23) -> 68 | F18: =D18/E18 -> 13.117647 | G18: =D18/$AB$4 -> 1.0079096 | H18: =ROUND(G18/0.7,0) -> 1 | I18: 1 | J18: 1 | K18: 3 | L18: 1 | M18: 1 | N18: 1 | O18: =H18 -> 1 | P18: 1 | Q18: 1 | S18: =H18 -> 1 | T18: =S18 -> 1 | U18: 1 | V18: =H18 -> 1 | W18: 1 | AC18: SAMSUN MERKEZ BAKIM | AD18: 68
A19: TERME BAKIM | B19: 1.5054104e+08 | C19: 46825381 | D19: 812 | E19: =_xlfn.XLOOKUP(A19,$AC$3:$AC$23,$AD$3:$AD$23) -> 51 | F19: =D19/E19 -> 15.921569 | G19: =D19/$AB$4 -> 0.91751412 | H19: =ROUND(G19/0.7,0) -> 1 | I19: 1 | J19: 1 | K19: 3 | L19: 1 | M19: 1 | N19: 1 | O19: =H19 -> 1 | P19: 1 | Q19: 1 | S19: =H19 -> 1 | T19: =S19 -> 1 | U19: 1 | V19: =H19 -> 1 | W19: 1 | AC19: SİNOP MERKEZ BAKIM | AD19: 58
A20: VEZİRKÖPRÜ BAKIM | B20: 3.053559e+08 | C20: 95095617 | D20: 1959 | E20: =_xlfn.XLOOKUP(A20,$AC$3:$AC$23,$AD$3:$AD$23) -> 69 | F20: =D20/E20 -> 28.391304 | G20: =D20/$AB$4 -> 2.2135593 | H20: =ROUND(G20/0.7,0) -> 3 | I20: 1 | J20: 1 | K20: 3 | L20: 1 | M20: 1 | N20: 1 | O20: =H20 -> 3 | P20: 1 | Q20: 1 | R20: 1 | S20: =H20 -> 3 | T20: =S20 -> 3 | U20: 1 | V20: =H20 -> 3 | W20: 1 | AC20: SUNGURLU BAKIM | AD20: 29
A21: SİNOP MERKEZ BAKIM | B21: 1.9866265e+08 | C21: 61775986 | D21: 1280 | E21: =_xlfn.XLOOKUP(A21,$AC$3:$AC$23,$AD$3:$AD$23) -> 58 | F21: =D21/E21 -> 22.068966 | G21: =D21/$AB$4 -> 1.4463277 | H21: =ROUND(G21/0.7,0) -> 2 | I21: 1 | J21: 1 | K21: 3 | L21: 1 | M21: 1 | N21: 1 | O21: =H21 -> 2 | P21: 1 | Q21: 1 | R21: 1 | S21: =H21 -> 2 | T21: =S21 -> 2 | U21: 1 | V21: =H21 -> 2 | W21: 1 | AC21: TERME BAKIM | AD21: 51
A22: AYANCIK BAKIM | B22: 1.5203558e+08 | C22: 47590446 | D22: 861 | E22: =_xlfn.XLOOKUP(A22,$AC$3:$AC$23,$AD$3:$AD$23) -> 55 | F22: =D22/E22 -> 15.654545 | G22: =D22/$AB$4 -> 0.97288136 | H22: =ROUND(G22/0.7,0) -> 1 | I22: 1 | J22: 1 | K22: 3 | L22: 1 | M22: 1 | N22: 1 | O22: =H22 -> 1 | P22: 1 | Q22: 1 | S22: =H22 -> 1 | T22: =S22 -> 1 | U22: 1 | V22: =H22 -> 1 | W22: 1 | AC22: ÜNYE BAKIM | AD22: 48
A23: BOYABAT BAKIM | B23: 1.9599206e+08 | C23: 62504532 | D23: 1095 | E23: =_xlfn.XLOOKUP(A23,$AC$3:$AC$23,$AD$3:$AD$23) -> 42 | F23: =D23/E23 -> 26.071429 | G23: =D23/$AB$4 -> 1.2372881 | H23: =ROUND(G23/0.7,0) -> 2 | I23: 1 | J23: 1 | K23: 3 | L23: 1 | M23: 1 | N23: 1 | O23: =H23 -> 2 | P23: 1 | Q23: 1 | R23: 1 | S23: =H23 -> 2 | T23: =S23 -> 2 | U23: 1 | V23: =H23 -> 2 | W23: 1 | AC23: VEZİRKÖPRÜ BAKIM | AD23: 69
B24: 4.0047997e+09 | C24: 1.2703033e+09 | D24: 24607 | F24: =AVERAGE(F3:F23) -> 23.520276 | H24: =SUBTOTAL(9,H3:H23) -> 39 | I24: =SUBTOTAL(9,I3:I23) -> 21 | J24: =SUBTOTAL(9,J3:J23) -> 21 | K24: =SUBTOTAL(9,K3:K23) -> 63 | L24: =SUBTOTAL(9,L3:L23) -> 21 | M24: =SUBTOTAL(9,M3:M23) -> 21 | N24: =SUBTOTAL(9,N3:N23) -> 21 | O24: =SUBTOTAL(9,O3:O23) -> 39 | ... W24: =SUBTOTAL(9,W3:W23) -> 21 | AD24: 1112
L25: =SUM(I24:L24) -> 126 | P25: =SUM(M24:P24) -> 102 | T25: =SUM(Q24:T24) -> 112 | W25: =SUM(U24:W24) -> 81
M26: TUNCER BEY | Q26: ALPAY BEY | S26: =39*6 -> 234
M27: TALHA BEY
M28: SİNAN BEY
M29: UĞUR BEY
M30: MUSTAFA BEY
